Workbook
Name SegmentaçãodeDados_CULTURA: #N/A

Sheet Resumo
B1: Cereal Ouro
B2: PCP - Planejamento e Controle de Produção
B3: Acompanhamento da Acuraciade dos Estoques de Sementes - 2025
B5: CULTURA | C5: (Tudo)
C7: LOCAL | D7: Valores
C8: LPCO | D8: LPCO | E8: UBS I | F8: UBS I
B9: MÊS | C9: Soma de N° Lotes | D9: % Acuracidade | E9: Soma de N° Lotes | F9: % Acuracidade
B10: ABR | C10: 287 | D10: 1 | E10: 347 | F10: 1
B11: MAI | C11: 287 | D11: 1 | E11: 340 | F11: 1
B12: JUN | C12: 287 | D12: 1 | E12: 376 | F12: 0.99951463
B13: JUL | C13: 204 | D13: 0.99501753 | E13: 334 | F13: 1
B14: Total Geral | C14: 1065 | D14: 0.99904906 | E14: 1397 | F14: 0.99984915

Sheet Resultados
A1: LOCAL | B1: UF | C1: Filial | D1: Deposito | E1: CULTURA | F1: LOTE | G1: CULTIVAR | H1: CÓD. PRODUTO | I1: NOME PRODUTO ERP | J1: CAT | K1: PEN. | L1: UM | M1: QTD SISTEMA | N1: PESO ETIQUETA | O1: CAT. FÍS. | P1: ETIQUETA FÍSICA | Q1: QTD FÍSICA | R1: CÂMARA | S1: QUADRA | T1: FILEIRA | U1: CONF.? (SIM/NÃO) | V1: N° Lotes | W1: DATA VERIFICAÇÃO | X1: MÊS | Y1: AUDITOR | Z1: AUDITOR | AA1: RESPONSÁVEL UBS
A2: LPCO | B2: GO | C2: 0101 | D2: 11 | E2: SOJA | F2: 11743P1417 | G2: 22213I2X | H2: PA154000849 | I2: SEM SOJA 22213I2X BG ST | J2: C2 | K2: P1 | L2: BG | M2: 30 | N2: 761 | O2: C2 | P2: 761 | Q2: 30 | U2: =IF(AUDITORIA[[#This Row],[QTD FÍSICA]]="","",IF(AND(AUDITORIA[[#This Row],[CAT]]=AUDITORIA[[#This Row],[CAT. FÍS.]],AUDITORIA[[#This Row],[QTD FÍSICA]]=AUDITORIA[[#This Row],[QTD SISTEMA]]),"SIM","NÃO")) -> SIM | V2: =IF(AUDITORIA[[#This Row],[CAT]]="",0,1) -> 1 | W2: 46135 | X2: =UPPER(IF(AUDITORIA[[#This Row],[DATA VERIFICAÇÃO]]="","",TEXT(AUDITORIA[[#This Row],[DATA VERIFICAÇÃO]],"mmm"))) -> ABR | Y2: Renato de Castro | Z2: Evelyn Ataide | AA2: Luziano Alves
A3: LPCO | B3: GO | C3: 0101 | D3: 11 | E3: SOJA | F3: 11743P1420 | G3: 22213I2X | H3: PA154000849 | I3: SEM SOJA 22213I2X BG ST | J3: C2 | K3: P1 | L3: BG | M3: 30 | N3: 733 | O3: C2 | P3: 733 | Q3: 30 | U3: =IF(AUDITORIA[[#This Row],[QTD FÍSICA]]="","",IF(AND(AUDITORIA[[#This Row],[CAT]]=AUDITORIA[[#This Row],[CAT. FÍS.]],AUDITORIA[[#This Row],[QTD FÍSICA]]=AUDITORIA[[#This Row],[QTD SISTEMA]]),"SIM","NÃO")) -> SIM | V3: =IF(AUDITORIA[[#This Row],[CAT]]="",0,1) -> 1 | W3: 46135 | X3: =UPPER(IF(AUDITORIA[[#This Row],[DATA VERIFICAÇÃO]]="","",TEXT(AUDITORIA[[#This Row],[DATA VERIFICAÇÃO]],"mmm"))) -> ABR | Y3: Renato de Castro | Z3: Evelyn Ataide | AA3: Luziano Alves
A4: LPCO | B4: GO | C4: 0101 | D4: 11 | E4: SOJA | F4: 11743P1422 | G4: 22213I2X | H4: PA154000849 | I4: SEM SOJA 22213I2X BG ST | J4: C2 | K4: P1 | L4: BG | M4: 30 | N4: 748 | O4: C2 | P4: 748 | Q4: 30 | U4: =IF(AUDITORIA[[#This Row],[QTD FÍSICA]]="","",IF(AND(AUDITORIA[[#This Row],[CAT]]=AUDITORIA[[#This Row],[CAT. FÍS.]],AUDITORIA[[#This Row],[QTD FÍSICA]]=AUDITORIA[[#This Row],[QTD SISTEMA]]),"SIM","NÃO")) -> SIM | V4: =IF(AUDITORIA[[#This Row],[CAT]]="",0,1) -> 1 | W4: 46135 | X4: =UPPER(IF(AUDITORIA[[#This Row],[DATA VERIFICAÇÃO]]="","",TEXT(AUDITORIA[[#This Row],[DATA VERIFICAÇÃO]],"mmm"))) -> ABR | Y4: Renato de Castro | Z4: Evelyn Ataide | AA4: Luziano Alves
A5: LPCO | B5: GO | C5: 0101 | D5: 11 | E5: SOJA | F5: 11743P1424 | G5: 22213I2X | H5: PA154000849 | I5: SEM SOJA 22213I2X BG ST | J5: C2 | K5: P1 | L5: BG | M5: 23 | N5: 731 | O5: C2 | P5: 731 | Q5: 23 | U5: =IF(AUDITORIA[[#This Row],[QTD FÍSICA]]="","",IF(AND(AUDITORIA[[#This Row],[CAT]]=AUDITORIA[[#This Row],[CAT. FÍS.]],AUDITORIA[[#This Row],[QTD FÍSICA]]=AUDITORIA[[#This Row],[QTD SISTEMA]]),"SIM","NÃO")) -> SIM | V5: =IF(AUDITORIA[[#This Row],[CAT]]="",0,1) -> 1 | W5: 46135 | X5: =UPPER(IF(AUDITORIA[[#This Row],[DATA VERIFICAÇÃO]]="","",TEXT(AUDITORIA[[#This Row],[DATA VERIFICAÇÃO]],"mmm"))) -> ABR | Y5: Renato de Castro | Z5: Evelyn Ataide | AA5: Luziano Alves
A6: LPCO | B6: GO | C6: 0101 | D6: 11 | E6: SOJA | F6: 11743P2418 | G6: 22213I2X | H6: PA154000849 | I6: SEM SOJA 22213I2X BG ST | J6: C2 | K6: P2 | L6: BG | M6: 27 | N6: 953 | O6: C2 | P6: 953 | Q6: 27 | U6: =IF(AUDITORIA[[#This Row],[QTD FÍSICA]]="","",IF(AND(AUDITORIA[[#This Row],[CAT]]=AUDITORIA[[#This Row],[CAT. FÍS.]],AUDITORIA[[#This Row],[QTD FÍSICA]]=AUDITORIA[[#This Row],[QTD SISTEMA]]),"SIM","NÃO")) -> SIM | V6: =IF(AUDITORIA[[#This Row],[CAT]]="",0,1) -> 1 | W6: 46135 | X6: =UPPER(IF(AUDITORIA[[#This Row],[DATA VERIFICAÇÃO]]="","",TEXT(AUDITORIA[[#This Row],[DATA VERIFICAÇÃO]],"mmm"))) -> ABR | Y6: Renato de Castro | Z6: Evelyn Ataide | AA6: Luziano Alves
A7: LPCO | B7: GO | C7: 0101 | D7: 11 | E7: SOJA | F7: 11743P2419 | G7: 22213I2X | H7: PA154000849 | I7: SEM SOJA 22213I2X BG ST | J7: C2 | K7: P2 | L7: BG | M7: 27 | N7: 936 | O7: C2 | P7: 936 | Q7: 27 | U7: =IF(AUDITORIA[[#This Row],[QTD FÍSICA]]="","",IF(AND(AUDITORIA[[#This Row],[CAT]]=AUDITORIA[[#This Row],[CAT. FÍS.]],AUDITORIA[[#This Row],[QTD FÍSICA]]=AUDITORIA[[#This Row],[QTD SISTEMA]]),"SIM","NÃO")) -> SIM | V7: =IF(AUDITORIA[[#This Row],[CAT]]="",0,1) -> 1 | W7: 46135 | X7: =UPPER(IF(AUDITORIA[[#This Row],[DATA VERIFICAÇÃO]]="","",TEXT(AUDITORIA[[#This Row],[DATA VERIFICAÇÃO]],"mmm"))) -> ABR | Y7: Renato de Castro | Z7: Evelyn Ataide | AA7: Luziano Alves
A8: LPCO | B8: GO | C8: 0101 | D8: 11 | E8: SOJA | F8: 11743P2421 | G8: 22213I2X | H8: PA154000849 | I8: SEM SOJA 22213I2X BG ST | J8: C2 | K8: P2 | L8: BG | M8: 27 | N8: 948 | O8: C2 | P8: 948 | Q8: 27 | U8: =IF(AUDITORIA[[#This Row],[QTD FÍSICA]]="","",IF(AND(AUDITORIA[[#This Row],[CAT]]=AUDITORIA[[#This Row],[CAT. FÍS.]],AUDITORIA[[#This Row],[QTD FÍSICA]]=AUDITORIA[[#This Row],[QTD SISTEMA]]),"SIM","NÃO")) -> SIM | V8: =IF(AUDITORIA[[#This Row],[CAT]]="",0,1) -> 1 | W8: 46135 | X8: =UPPER(IF(AUDITORIA[[#This Row],[DATA VERIFICAÇÃO]]="","",TEXT(AUDITORIA[[#This Row],[DATA VERIFICAÇÃO]],"mmm"))) -> ABR | Y8: Renato de Castro | Z8: Evelyn Ataide | AA8: Luziano Alves
A9: LPCO | B9: GO | C9: 0101 | D9: 11 | E9: SOJA | F9: 11743P2423 | G9: 22213I2X | H9: PA154000849 | I9: SEM SOJA 22213I2X BG ST | J9: C2 | K9: P2 | L9: BG | M9: 27 | N9: 929 | O9: C2 | P9: 929 | Q9: 27 | U9: =IF(AUDITORIA[[#This Row],[QTD FÍSICA]]="","",IF(AND(AUDITORIA[[#This Row],[CAT]]=AUDITORIA[[#This Row],[CAT. FÍS.]],AUDITORIA[[#This Row],[QTD FÍSICA]]=AUDITORIA[[#This Row],[QTD SISTEMA]]),"SIM","NÃO")) -> SIM | V9: =IF(AUDITORIA[[#This Row],[CAT]]="",0,1) -> 1 | W9: 46135 | X9: =UPPER(IF(AUDITORIA[[#This Row],[DATA VERIFICAÇÃO]]="","",TEXT(AUDITORIA[[#This Row],[DATA VERIFICAÇÃO]],"mmm"))) -> ABR | Y9: Renato de Castro | Z9: Evelyn Ataide | AA9: Luziano Alves
A10: LPCO | B10: GO | C10: 0101 | D10: 11 | E10: SOJA | F10: 11743P2425 | G10: 22213I2X | H10: PA154000849 | I10: SEM SOJA 22213I2X BG ST | J10: C2 | K10: P2 | L10: BG | M10: 14 | N10: 949 | O10: C2 | P10: 949 | Q10: 14 | U10: =IF(AUDITORIA[[#This Row],[QTD FÍSICA]]="","",IF(AND(AUDITORIA[[#This Row],[CAT]]=AUDITORIA[[#This Row],[CAT. FÍS.]],AUDITORIA[[#This Row],[QTD FÍSICA]]=AUDITORIA[[#This Row],[QTD SISTEMA]]),"SIM","NÃO")) -> SIM | V10: =IF(AUDITORIA[[#This Row],[CAT]]="",0,1) -> 1 | W10: 46135 | X10: =UPPER(IF(AUDITORIA[[#This Row],[DATA VERIFICAÇÃO]]="","",TEXT(AUDITORIA[[#This Row],[DATA VERIFICAÇÃO]],"mmm"))) -> ABR | Y10: Renato de Castro | Z10: Evelyn Ataide | AA10: Luziano Alves
A11: LPCO | B11: GO | C11: 0101 | D11: 11 | E11: SOJA | F11: 11272P1201 | G11: 690 I2X | H11: PA154000454 | I11: SEM SOJA 690 I2X BG ST | J11: S1 | K11: P1 | L11: BG | M11: 30 | N11: 759 | O11: S1 | P11: 759 | Q11: 30 | U11: =IF(AUDITORIA[[#This Row],[QTD FÍSICA]]="","",IF(AND(AUDITORIA[[#This Row],[CAT]]=AUDITORIA[[#This Row],[CAT. FÍS.]],AUDITORIA[[#This Row],[QTD FÍSICA]]=AUDITORIA[[#This Row],[QTD SISTEMA]]),"SIM","NÃO")) -> SIM | V11: =IF(AUDITORIA[[#This Row],[CAT]]="",0,1) -> 1 | W11: 46135 | X11: =UPPER(IF(AUDITORIA[[#This Row],[DATA VERIFICAÇÃO]]="","",TEXT(AUDITORIA[[#This Row],[DATA VERIFICAÇÃO]],"mmm"))) -> ABR | Y11: Renato de Castro | Z11: Evelyn Ataide | AA11: Luziano Alves
A12: LPCO | B12: GO | C12: 0101 | D12: 11 | E12: SOJA | F12: 11272P1203 | G12: 690 I2X | H12: PA154000454 | I12: SEM SOJA 690 I2X BG ST | J12: S1 | K12: P1 | L12: BG | M12: 30 | N12: 742 | O12: S1 | P12: 742 | Q12: 30 | U12: =IF(AUDITORIA[[#This Row],[QTD FÍSICA]]="","",IF(AND(AUDITORIA[[#This Row],[CAT]]=AUDITORIA[[#This Row],[CAT. FÍS.]],AUDITORIA[[#This Row],[QTD FÍSICA]]=AUDITORIA[[#This Row],[QTD SISTEMA]]),"SIM","NÃO")) -> SIM | V12: =IF(AUDITORIA[[#This Row],[CAT]]="",0,1) -> 1 | W12: 46135 | X12: =UPPER(IF(AUDITORIA[[#This Row],[DATA VERIFICAÇÃO]]="","",TEXT(AUDITORIA[[#This Row],[DATA VERIFICAÇÃO]],"mmm"))) -> ABR | Y12: Renato de Castro | Z12: Evelyn Ataide | AA12: Luziano Alves
A13: LPCO | B13: GO | C13: 0101 | D13: 11 | E13: SOJA | F13: 11272P1205 | G13: 690 I2X | H13: PA154000454 | I13: SEM SOJA 690 I2X BG ST | J13: S1 | K13: P1 | L13: BG | M13: 30 | N13: 755 | O13: S1 | P13: 755 | Q13: 30 | U13: =IF(AUDITORIA[[#This Row],[QTD FÍSICA]]="","",IF(AND(AUDITORIA[[#This Row],[CAT]]=AUDITORIA[[#This Row],[CAT. FÍS.]],AUDITORIA[[#This Row],[QTD FÍSICA]]=AUDITORIA[[#This Row],[QTD SISTEMA]]),"SIM","NÃO")) -> SIM | V13: =IF(AUDITORIA[[#This Row],[CAT]]="",0,1) -> 1 | W13: 46135 | X13: =UPPER(IF(AUDITORIA[[#This Row],[DATA VERIFICAÇÃO]]="","",TEXT(AUDITORIA[[#This Row],[DATA VERIFICAÇÃO]],"mmm"))) -> ABR | Y13: Renato de Castro | Z13: Evelyn Ataide | AA13: Luziano Alves
... A288: LPCO | B288: GO | C288: 0101 | D288: 11 | E288: SOJA | F288: 11264P2433 | G288: O820 IPRO | H288: PA154001160 | I288: SOJA DEST STE O820 IPRO BG ST | J288: S1 | K288: P2 | L288: BG | M288: 4 | N288: 1193 | O288: S1 | P288: 1193 | Q288: 4 | U288: =IF(AUDITORIA[[#This Row],[QTD FÍSICA]]="","",IF(AND(AUDITORIA[[#This Row],[CAT]]=AUDITORIA[[#This Row],[CAT. FÍS.]],AUDITORIA[[#This Row],[QTD FÍSICA]]=AUDITORIA[[#This Row],[QTD SISTEMA]]),"SIM","NÃO")) -> SIM | V288: =IF(AUDITORIA[[#This Row],[CAT]]="",0,1) -> 1 | W288: 46135 | X288: =UPPER(IF(AUDITORIA[[#This Row],[DATA VERIFICAÇÃO]]="","",TEXT(AUDITORIA[[#This Row],[DATA VERIFICAÇÃO]],"mmm"))) -> ABR | Y288: Renato de Castro | Z288: Evelyn Ataide | AA288: Luziano Alves
A289: UBS I | B289: GO | C289: 0101 | D289: 10 | E289: SOJA | F289: 11026715P1061 | G289: 761 I2X | J289: S2 | K289: P1 | L289: BG | M289: 30 | N289: 814 | O289: S2 | P289: 814 | Q289: 30 | U289: =IF(AUDITORIA[[#This Row],[QTD FÍSICA]]="","",IF(AND(AUDITORIA[[#This Row],[CAT]]=AUDITORIA[[#This Row],[CAT. FÍS.]],AUDITORIA[[#This Row],[QTD FÍSICA]]=AUDITORIA[[#This Row],[QTD SISTEMA]]),"SIM","NÃO")) -> SIM | V289: =IF(AUDITORIA[[#This Row],[CAT]]="",0,1) -> 1 | W289: 46141 | X289: =UPPER(IF(AUDITORIA[[#This Row],[DATA VERIFICAÇÃO]]="","",TEXT(AUDITORIA[[#This Row],[DATA VERIFICAÇÃO]],"mmm"))) -> ABR | Y289: Renato de Castro | Z289: Sergio Mench do Prado | AA289: Cláudio Mecenas
A290: UBS I | B290: GO | C290: 0101 | D290: 10 | E290: SOJA | F290: 11026715P1063 | G290: 761 I2X | J290: S2 | K290: P1 | L290: BG | M290: 30 | N290: 824 | O290: S2 | P290: 824 | Q290: 30 | U290: =IF(AUDITORIA[[#This Row],[QTD FÍSICA]]="","",IF(AND(AUDITORIA[[#This Row],[CAT]]=AUDITORIA[[#This Row],[CAT. FÍS.]],AUDITORIA[[#This Row],[QTD FÍSICA]]=AUDITORIA[[#This Row],[QTD SISTEMA]]),"SIM","NÃO")) -> SIM | V290: =IF(AUDITORIA[[#This Row],[CAT]]="",0,1) -> 1 | W290: 46141 | X290: =UPPER(IF(AUDITORIA[[#This Row],[DATA VERIFICAÇÃO]]="","",TEXT(AUDITORIA[[#This Row],[DATA VERIFICAÇÃO]],"mmm"))) -> ABR | Y290: Renato de Castro | Z290: Sergio Mench do Prado | AA290: Cláudio Mecenas
A291: UBS I | B291: GO | C291: 0101 | D291: 10 | E291: SOJA | F291: 11026715P1067 | G291: 761 I2X | J291: S2 | K291: P1 | L291: BG | M291: 30 | N291: 810 | O291: S2 | P291: 810 | Q291: 30 | U291: =IF(AUDITORIA[[#This Row],[QTD FÍSICA]]="","",IF(AND(AUDITORIA[[#This Row],[CAT]]=AUDITORIA[[#This Row],[CAT. FÍS.]],AUDITORIA[[#This Row],[QTD FÍSICA]]=AUDITORIA[[#This Row],[QTD SISTEMA]]),"SIM","NÃO")) -> SIM | V291: =IF(AUDITORIA[[#This Row],[CAT]]="",0,1) -> 1 | W291: 46141 | X291: =UPPER(IF(AUDITORIA[[#This Row],[DATA VERIFICAÇÃO]]="","",TEXT(AUDITORIA[[#This Row],[DATA VERIFICAÇÃO]],"mmm"))) -> ABR | Y291: Renato de Castro | Z291: Sergio Mench do Prado | AA291: Cláudio Mecenas
A292: UBS I | B292: GO | C292: 0101 | D292: 10 | E292: SOJA | F292: 11026715P1069 | G292: 761 I2X | J292: S2 | K292: P1 | L292: BG | M292: 30 | N292: 819 | O292: S2 | P292: 819 | Q292: 30 | U292: =IF(AUDITORIA[[#This Row],[QTD FÍSICA]]="","",IF(AND(AUDITORIA[[#This Row],[CAT]]=AUDITORIA[[#This Row],[CAT. FÍS.]],AUDITORIA[[#This Row],[QTD FÍSICA]]=AUDITORIA[[#This Row],[QTD SISTEMA]]),"SIM","NÃO")) -> SIM | V292: =IF(AUDITORIA[[#This Row],[CAT]]="",0,1) -> 1 | W292: 46141 | X292: =UPPER(IF(AUDITORIA[[#This Row],[DATA VERIFICAÇÃO]]="","",TEXT(AUDITORIA[[#This Row],[DATA VERIFICAÇÃO]],"mmm"))) -> ABR | Y292: Renato de Castro | Z292: Sergio Mench do Prado | AA292: Cláudio Mecenas
A293: UBS I | B293: GO | C293: 0101 | D293: 10 | E293: SOJA | F293: 11026715P1073 | G293: 761 I2X | J293: S2 | K293: P1 | L293: BG | M293: 30 | N293: 823 | O293: S2 | P293: 823 | Q293: 30 | U293: =IF(AUDITORIA[[#This Row],[QTD FÍSICA]]="","",IF(AND(AUDITORIA[[#This Row],[CAT]]=AUDITORIA[[#This Row],[CAT. FÍS.]],AUDITORIA[[#This Row],[QTD FÍSICA]]=AUDITORIA[[#This Row],[QTD SISTEMA]]),"SIM","NÃO")) -> SIM | V293: =IF(AUDITORIA[[#This Row],[CAT]]="",0,1) -> 1 | W293: 46141 | X293: =UPPER(IF(AUDITORIA[[#This Row],[DATA VERIFICAÇÃO]]="","",TEXT(AUDITORIA[[#This Row],[DATA VERIFICAÇÃO]],"mmm"))) -> ABR | Y293: Renato de Castro | Z293: Sergio Mench do Prado | AA293: Cláudio Mecenas
A294: UBS I | B294: GO | C294: 0101 | D294: 10 | E294: SOJA | F294: 11026715P1076 | G294: 761 I2X | J294: S2 | K294: P1 | L294: BG | M294: 30 | N294: 804 | O294: S2 | P294: 804 | Q294: 30 | U294: =IF(AUDITORIA[[#This Row],[QTD FÍSICA]]="","",IF(AND(AUDITORIA[[#This Row],[CAT]]=AUDITORIA[[#This Row],[CAT. FÍS.]],AUDITORIA[[#This Row],[QTD FÍSICA]]=AUDITORIA[[#This Row],[QTD SISTEMA]]),"SIM","NÃO")) -> SIM | V294: =IF(AUDITORIA[[#This Row],[CAT]]="",0,1) -> 1 | W294: 46141 | X294: =UPPER(IF(AUDITORIA[[#This Row],[DATA VERIFICAÇÃO]]="","",TEXT(AUDITORIA[[#This Row],[DATA VERIFICAÇÃO]],"mmm"))) -> ABR | Y294: Renato de Castro | Z294: Sergio Mench do Prado | AA294: Cláudio Mecenas
A295: UBS I | B295: GO | C295: 0101 | D295: 10 | E295: SOJA | F295: 11026715P1079 | G295: 761 I2X | J295: S2 | K295: P1 | L295: BG | M295: 30 | N295: 814 | O295: S2 | P295: 814 | Q295: 30 | U295: =IF(AUDITORIA[[#This Row],[QTD FÍSICA]]="","",IF(AND(AUDITORIA[[#This Row],[CAT]]=AUDITORIA[[#This Row],[CAT. FÍS.]],AUDITORIA[[#This Row],[QTD FÍSICA]]=AUDITORIA[[#This Row],[QTD SISTEMA]]),"SIM","NÃO")) -> SIM | V295: =IF(AUDITORIA[[#This Row],[CAT]]="",0,1) -> 1 | W295: 46141 | X295: =UPPER(IF(AUDITORIA[[#This Row],[DATA VERIFICAÇÃO]]="","",TEXT(AUDITORIA[[#This Row],[DATA VERIFICAÇÃO]],"mmm"))) -> ABR | Y295: Renato de Castro | Z295: Sergio Mench do Prado | AA295: Cláudio Mecenas
A296: UBS I | B296: GO | C296: 0101 | D296: 10 | E296: SOJA | F296: 11026715P1083 | G296: 761 I2X | J296: S2 | K296: P1 | L296: BG | M296: 30 | N296: 793 | O296: S2 | P296: 793 | Q296: 30 | U296: =IF(AUDITORIA[[#This Row],[QTD FÍSICA]]="","",IF(AND(AUDITORIA[[#This Row],[CAT]]=AUDITORIA[[#This Row],[CAT. FÍS.]],AUDITORIA[[#This Row],[QTD FÍSICA]]=AUDITORIA[[#This Row],[QTD SISTEMA]]),"SIM","NÃO")) -> SIM | V296: =IF(AUDITORIA[[#This Row],[CAT]]="",0,1) -> 1 | W296: 46141 | X296: =UPPER(IF(AUDITORIA[[#This Row],[DATA VERIFICAÇÃO]]="","",TEXT(AUDITORIA[[#This Row],[DATA VERIFICAÇÃO]],"mmm"))) -> ABR | Y296: Renato de Castro | Z296: Sergio Mench do Prado | AA296: Cláudio Mecenas
A297: UBS I | B297: GO | C297: 0101 | D297: 10 | E297: SOJA | F297: 11026715P1087 | G297: 761 I2X | J297: C1 | K297: P1 | L297: BG | M297: 30 | N297: 825 | O297: C1 | P297: 825 | Q297: 30 | U297: =IF(AUDITORIA[[#This Row],[QTD FÍSICA]]="","",IF(AND(AUDITORIA[[#This Row],[CAT]]=AUDITORIA[[#This Row],[CAT. FÍS.]],AUDITORIA[[#This Row],[QTD FÍSICA]]=AUDITORIA[[#This Row],[QTD SISTEMA]]),"SIM","NÃO")) -> SIM | V297: =IF(AUDITORIA[[#This Row],[CAT]]="",0,1) -> 1 | W297: 46141 | X297: =UPPER(IF(AUDITORIA[[#This Row],[DATA VERIFICAÇÃO]]="","",TEXT(AUDITORIA[[#This Row],[DATA VERIFICAÇÃO]],"mmm"))) -> ABR | Y297: Renato de Castro | Z297: Sergio Mench do Prado | AA297: Cláudio Mecenas
A298: UBS I | B298: GO | C298: 0101 | D298: 10 | E298: SOJA | F298: 11026715P1090 | G298: 761 I2X | J298: C1 | K298: P1 | L298: BG | M298: 12 | N298: 804 | O298: C1 | P298: 804 | Q298: 12 | U298: =IF(AUDITORIA[[#This Row],[QTD FÍSICA]]="","",IF(AND(AUDITORIA[[#This Row],[CAT]]=AUDITORIA[[#This Row],[CAT. FÍS.]],AUDITORIA[[#This Row],[QTD FÍSICA]]=AUDITORIA[[#This Row],[QTD SISTEMA]]),"SIM","NÃO")) -> SIM | V298: =IF(AUDITORIA[[#This Row],[CAT]]="",0,1) -> 1 | W298: 46141 | X298: =UPPER(IF(AUDITORIA[[#This Row],[DATA VERIFICAÇÃO]]="","",TEXT(AUDITORIA[[#This Row],[DATA VERIFICAÇÃO]],"mmm"))) -> ABR | Y298: Renato de Castro | Z298: Sergio Mench do Prado | AA298: Cláudio Mecenas
A299: UBS I | B299: GO | C299: 0101 | D299: 10 | E299: SOJA | F299: 11026715P1153 | G299: 761 I2X | J299: C1 | K299: P1 | L299: BG | M299: 30 | N299: 828 | O299: C1 | P299: 828 | Q299: 30 | U299: =IF(AUDITORIA[[#This Row],[QTD FÍSICA]]="","",IF(AND(AUDITORIA[[#This Row],[CAT]]=AUDITORIA[[#This Row],[CAT. FÍS.]],AUDITORIA[[#This Row],[QTD FÍSICA]]=AUDITORIA[[#This Row],[QTD SISTEMA]]),"SIM","NÃO")) -> SIM | V299: =IF(AUDITORIA[[#This Row],[CAT]]="",0,1) -> 1 | W299: 46141 | X299: =UPPER(IF(AUDITORIA[[#This Row],[DATA VERIFICAÇÃO]]="","",TEXT(AUDITORIA[[#This Row],[DATA VERIFICAÇÃO]],"mmm"))) -> ABR | Y299: Renato de Castro | Z299: Sergio Mench do Prado | AA299: Cláudio Mecenas
A300: UBS I | B300: GO | C300: 0101 | D300: 10 | E300: SOJA | F300: 11026715P1156 | G300: 761 I2X | J300: S2 | K300: P1 | L300: BG | M300: 30 | N300: 804 | O300: S2 | P300: 804 | Q300: 30 | U300: =IF(AUDITORIA[[#This Row],[QTD FÍSICA]]="","",IF(AND(AUDITORIA[[#This Row],[CAT]]=AUDITORIA[[#This Row],[CAT. FÍS.]],AUDITORIA[[#This Row],[QTD FÍSICA]]=AUDITORIA[[#This Row],[QTD SISTEMA]]),"SIM","NÃO")) -> SIM | V300: =IF(AUDITORIA[[#This Row],[CAT]]="",0,1) -> 1 | W300: 46141 | X300: =UPPER(IF(AUDITORIA[[#This Row],[DATA VERIFICAÇÃO]]="","",TEXT(AUDITORIA[[#This Row],[DATA VERIFICAÇÃO]],"mmm"))) -> ABR | Y300: Renato de Castro | Z300: Sergio Mench do Prado | AA300: Cláudio Mecenas
... A361: UBS I | B361: GO | C361: 0101 | D361: 10 | E361: SOJA | F361: 11026756P2236 | G361: C2810CE | J361: C1 | K361: P2 | L361: BG | M361: 12 | N361: 852 | O361: C1 | P361: 852 | Q361: 12 | U361: =IF(AUDITORIA[[#This Row],[QTD FÍSICA]]="","",IF(AND(AUDITORIA[[#This Row],[CAT]]=AUDITORIA[[#This Row],[CAT. FÍS.]],AUDITORIA[[#This Row],[QTD FÍSICA]]=AUDITORIA[[#This Row],[QTD SISTEMA]]),"SIM","NÃO")) -> SIM | V361: =IF(AUDITORIA[[#This Row],[CAT]]="",0,1) -> 1 | W361: 46141 | X361: =UPPER(IF(AUDITORIA[[#This Row],[DATA VERIFICAÇÃO]]="","",TEXT(AUDITORIA[[#This Row],[DATA VERIFICAÇÃO]],"mmm"))) -> ABR | Y361: Renato de Castro | Z361: Sergio Mench do Prado | AA361: Cláudio Mecenas
A362: UBS I | B362: GO | C362: 0101 | D362: 10 | E362: MILHO | F362: 242504306 | G362: CRV2874 PRO4 | J362: S1 | L362: SC | M362: 1 | O362: S1 | Q362: 1 | U362: =IF(AUDITORIA[[#This Row],[QTD FÍSICA]]="","",IF(AND(AUDITORIA[[#This Row],[CAT]]=AUDITORIA[[#This Row],[CAT. FÍS.]],AUDITORIA[[#This Row],[QTD FÍSICA]]=AUDITORIA[[#This Row],[QTD SISTEMA]]),"SIM","NÃO")) -> SIM | V362: =IF(AUDITORIA[[#This Row],[CAT]]="",0,1) -> 1 | W362: 46141 | X362: =UPPER(IF(AUDITORIA[[#This Row],[DATA VERIFICAÇÃO]]="","",TEXT(AUDITORIA[[#This Row],[DATA VERIFICAÇÃO]],"mmm"))) -> ABR | Y362: Renato de Castro | Z362: Sergio Mench do Prado | AA362: Cláudio Mecenas
A363: UBS I | B363: GO | C363: 0101 | D363: 10 | E363: MILHO | F363: CRV2I04002 | G363: CRV2874 PRO4 | J363: S1 | K363: R3L | L363: SC | M363: 61 | O363: S1 | Q363: 61 | U363: =IF(AUDITORIA[[#This Row],[QTD FÍSICA]]="","",IF(AND(AUDITORIA[[#This Row],[CAT]]=AUDITORIA[[#This Row],[CAT. FÍS.]],AUDITORIA[[#This Row],[QTD FÍSICA]]=AUDITORIA[[#This Row],[QTD SISTEMA]]),"SIM","NÃO")) -> SIM | V363: =IF(AUDITORIA[[#This Row],[CAT]]="",0,1) -> 1 | W363: 46141 | X363: =UPPER(IF(AUDITORIA[[#This Row],[DATA VERIFICAÇÃO]]="","",TEXT(AUDITORIA[[#This Row],[DATA VERIFICAÇÃO]],"mmm"))) -> ABR | Y363: Renato de Castro | Z363: Sergio Mench do Prado | AA363: Cláudio Mecenas
A364: UBS I | B364: GO | C364: 0101 | D364: 10 | E364: MILHO | F364: CRV2I04016 | G364: CRV2874 PRO4 | J364: S1 | K364: C3C | L364: SC | M364: 8 | O364: S1 | Q364: 8 | U364: =IF(AUDITORIA[[#This Row],[QTD FÍSICA]]="","",IF(AND(AUDITORIA[[#This Row],[CAT]]=AUDITORIA[[#This Row],[CAT. FÍS.]],AUDITORIA[[#This Row],[QTD FÍSICA]]=AUDITORIA[[#This Row],[QTD SISTEMA]]),"SIM","NÃO")) -> SIM | V364: =IF(AUDITORIA[[#This Row],[CAT]]="",0,1) -> 1 | W364: 46141 | X364: =UPPER(IF(AUDITORIA[[#This Row],[DATA VERIFICAÇÃO]]="","",TEXT(AUDITORIA[[#This Row],[DATA VERIFICAÇÃO]],"mmm"))) -> ABR | Y364: Renato de Castro | Z364: Sergio Mench do Prado | AA364: Cláudio Mecenas
A365: UBS I | B365: GO | C365: 0101 | D365: 10 | E365: MILHO | F365: CRV2I04018 | G365: CRV2874 PRO4 | J365: S1 | K365: R4C | L365: SC | M365: 16 | O365: S1 | Q365: 16 | U365: =IF(AUDITORIA[[#This Row],[QTD FÍSICA]]="","",IF(AND(AUDITORIA[[#This Row],[CAT]]=AUDITORIA[[#This Row],[CAT. FÍS.]],AUDITORIA[[#This Row],[QTD FÍSICA]]=AUDITORIA[[#This Row],[QTD SISTEMA]]),"SIM","NÃO")) -> SIM | V365: =IF(AUDITORIA[[#This Row],[CAT]]="",0,1) -> 1 | W365: 46141 | X365: =UPPER(IF(AUDITORIA[[#This Row],[DATA VERIFICAÇÃO]]="","",TEXT(AUDITORIA[[#This Row],[DATA VERIFICAÇÃO]],"mmm"))) -> ABR | Y365: Renato de Castro | Z365: Sergio Mench do Prado | AA365: Cláudio Mecenas
A366: UBS I | B366: GO | C366: 0101 | D366: 10 | E366: MILHO | F366: CRV2I04020 | G366: CRV2874 PRO4 | J366: S1 | K366: C4C | L366: SC | M366: 36 | O366: S1 | Q366: 36 | U366: =IF(AUDITORIA[[#This Row],[QTD FÍSICA]]="","",IF(AND(AUDITORIA[[#This Row],[CAT]]=AUDITORIA[[#This Row],[CAT. FÍS.]],AUDITORIA[[#This Row],[QTD FÍSICA]]=AUDITORIA[[#This Row],[QTD SISTEMA]]),"SIM","NÃO")) -> SIM | V366: =IF(AUDITORIA[[#This Row],[CAT]]="",0,1) -> 1 | W366: 46141 | X366: =UPPER(IF(AUDITORIA[[#This Row],[DATA VERIFICAÇÃO]]="","",TEXT(AUDITORIA[[#This Row],[DATA VERIFICAÇÃO]],"mmm"))) -> ABR | Y366: Renato de Castro | Z366: Sergio Mench do Prado | AA366: Cláudio Mecenas
A367: UBS I | B367: GO | C367: 0101 | D367: 10 | E367: MILHO | F367: CRV2I04021 | G367: CRV2874 PRO4 | J367: S1 | K367: R5C | L367: SC | M367: 11 | O367: S1 | Q367: 11 | U367: =IF(AUDITORIA[[#This Row],[QTD FÍSICA]]="","",IF(AND(AUDITORIA[[#This Row],[CAT]]=AUDITORIA[[#This Row],[CAT. FÍS.]],AUDITORIA[[#This Row],[QTD FÍSICA]]=AUDITORIA[[#This Row],[QTD SISTEMA]]),"SIM","NÃO")) -> SIM | V367: =IF(AUDITORIA[[#This Row],[CAT]]="",0,1) -> 1 | W367: 46141 | X367: =UPPER(IF(AUDITORIA[[#This Row],[DATA VERIFICAÇÃO]]="","",TEXT(AUDITORIA[[#This Row],[DATA VERIFICAÇÃO]],"mmm"))) -> ABR | Y367: Renato de Castro | Z367: Sergio Mench do Prado | AA367: Cláudio Mecenas
A368: UBS I | B368: GO | C368: 0101 | D368: 10 | E368: MILHO | F368: CRV2I04022 | G368: CRV2874 PRO4 | J368: S1 | K368: C5L | L368: SC | M368: 23 | O368: S1 | Q368: 23 | U368: =IF(AUDITORIA[[#This Row],[QTD FÍSICA]]="","",IF(AND(AUDITORIA[[#This Row],[CAT]]=AUDITORIA[[#This Row],[CAT. FÍS.]],AUDITORIA[[#This Row],[QTD FÍSICA]]=AUDITORIA[[#This Row],[QTD SISTEMA]]),"SIM","NÃO")) -> SIM | V368: =IF(AUDITORIA[[#This Row],[CAT]]="",0,1) -> 1 | W368: 46141 | X368: =UPPER(IF(AUDITORIA[[#This Row],[DATA VERIFICAÇÃO]]="","",TEXT(AUDITORIA[[#This Row],[DATA VERIFICAÇÃO]],"mmm"))) -> ABR | Y368: Renato de Castro | Z368: Sergio Mench do Prado | AA368: Cláudio Mecenas
A369: UBS I | B369: GO | C369: 0101 | D369: 10 | E369: MILHO | F369: CRV2I04025 | G369: CRV2874 PRO4 | J369: S1 | K369: C5C | L369: SC | M369: 3 | O369: S1 | Q369: 3 | U369: =IF(AUDITORIA[[#This Row],[QTD FÍSICA]]="","",IF(AND(AUDITORIA[[#This Row],[CAT]]=AUDITORIA[[#This Row],[CAT. FÍS.]],AUDITORIA[[#This Row],[QTD FÍSICA]]=AUDITORIA[[#This Row],[QTD SISTEMA]]),"SIM","NÃO")) -> SIM | V369: =IF(AUDITORIA[[#This Row],[CAT]]="",0,1) -> 1 | W369: 46141 | X369: =UPPER(IF(AUDITORIA[[#This Row],[DATA VERIFICAÇÃO]]="","",TEXT(AUDITORIA[[#This Row],[DATA VERIFICAÇÃO]],"mmm"))) -> ABR | Y369: Renato de Castro | Z369: Sergio Mench do Prado | AA369: Cláudio Mecenas
A370: UBS I | B370: GO | C370: 0101 | D370: 10 | E370: MILHO | F370: CRV2I05007 | G370: CRV2874 PRO4 | J370: S1 | K370: R4C | L370: SC | M370: 87 | O370: S1 | Q370: 87 | U370: =IF(AUDITORIA[[#This Row],[QTD FÍSICA]]="","",IF(AND(AUDITORIA[[#This Row],[CAT]]=AUDITORIA[[#This Row],[CAT. FÍS.]],AUDITORIA[[#This Row],[QTD FÍSICA]]=AUDITORIA[[#This Row],[QTD SISTEMA]]),"SIM","NÃO")) -> SIM | V370: =IF(AUDITORIA[[#This Row],[CAT]]="",0,1) -> 1 | W370: 46141 | X370: =UPPER(IF(AUDITORIA[[#This Row],[DATA VERIFICAÇÃO]]="","",TEXT(AUDITORIA[[#This Row],[DATA VERIFICAÇÃO]],"mmm"))) -> ABR | Y370: Renato de Castro | Z370: Sergio Mench do Prado | AA370: Cláudio Mecenas
A371: UBS I | B371: GO | C371: 0101 | D371: 10 | E371: MILHO | F371: CRV2I05010 | G371: CRV2874 PRO4 | J371: S1 | L371: SC | M371: 305 | O371: S1 | Q371: 305 | U371: =IF(AUDITORIA[[#This Row],[QTD FÍSICA]]="","",IF(AND(AUDITORIA[[#This Row],[CAT]]=AUDITORIA[[#This Row],[CAT. FÍS.]],AUDITORIA[[#This Row],[QTD FÍSICA]]=AUDITORIA[[#This Row],[QTD SISTEMA]]),"SIM","NÃO")) -> SIM | V371: =IF(AUDITORIA[[#This Row],[CAT]]="",0,1) -> 1 | W371: 46141 | X371: =UPPER(IF(AUDITORIA[[#This Row],[DATA VERIFICAÇÃO]]="","",TEXT(AUDITORIA[[#This Row],[DATA VERIFICAÇÃO]],"mmm"))) -> ABR | Y371: Renato de Castro | Z371: Sergio Mench do Prado | AA371: Cláudio Mecenas
A372: UBS I | B372: GO | C372: 0101 | D372: 10 | E372: MILHO | F372: CRV2I05012 | G372: CRV2874 PRO4 | J372: S1 | K372: C5L | L372: SC | M372: 204 | O372: S1 | Q372: 204 | U372: =IF(AUDITORIA[[#This Row],[QTD FÍSICA]]="","",IF(AND(AUDITORIA[[#This Row],[CAT]]=AUDITORIA[[#This Row],[CAT. FÍS.]],AUDITORIA[[#This Row],[QTD FÍSICA]]=AUDITORIA[[#This Row],[QTD SISTEMA]]),"SIM","NÃO")) -> SIM | V372: =IF(AUDITORIA[[#This Row],[CAT]]="",0,1) -> 1 | W372: 46141 | X372: =UPPER(IF(AUDITORIA[[#This Row],[DATA VERIFICAÇÃO]]="","",TEXT(AUDITORIA[[#This Row],[DATA VERIFICAÇÃO]],"mmm"))) -> ABR | Y372: Renato de Castro | Z372: Sergio Mench do Prado | AA372: Cláudio Mecenas
A373: UBS I | B373: GO | C373: 0101 | D373: 10 | E373: MILHO | F373: CRV2I05014 | G373: CRV2874 PRO4 | J373: S1 | K373: C3L | L373: SC | M373: 12 | O373: S1 | Q373: 12 | U373: =IF(AUDITORIA[[#This Row],[QTD FÍSICA]]="","",IF(AND(AUDITORIA[[#This Row],[CAT]]=AUDITORIA[[#This Row],[CAT. FÍS.]],AUDITORIA[[#This Row],[QTD FÍSICA]]=AUDITORIA[[#This Row],[QTD SISTEMA]]),"SIM","NÃO")) -> SIM | V373: =IF(AUDITORIA[[#This Row],[CAT]]="",0,1) -> 1 | W373: 46141 | X373: =UPPER(IF(AUDITORIA[[#This Row],[DATA VERIFICAÇÃO]]="","",TEXT(AUDITORIA[[#This Row],[DATA VERIFICAÇÃO]],"mmm"))) -> ABR | Y373: Renato de Castro | Z373: Sergio Mench do Prado | AA373: Cláudio Mecenas
A374: UBS I | B374: GO | C374: 0101 | D374: 10 | E374: MILHO | F374: CRV2I05016 | G374: CRV2874 PRO4 | J374: S1 | K374: C4L | L374: SC | M374: 162 | O374: S1 | Q374: 162 | U374: =IF(AUDITORIA[[#This Row],[QTD FÍSICA]]="","",IF(AND(AUDITORIA[[#This Row],[CAT]]=AUDITORIA[[#This Row],[CAT. FÍS.]],AUDITORIA[[#This Row],[QTD FÍSICA]]=AUDITORIA[[#This Row],[QTD SISTEMA]]),"SIM","NÃO")) -> SIM | V374: =IF(AUDITORIA[[#This Row],[CAT]]="",0,1) -> 1 | W374: 46141 | X374: =UPPER(IF(AUDITORIA[[#This Row],[DATA VERIFICAÇÃO]]="","",TEXT(AUDITORIA[[#This Row],[DATA VERIFICAÇÃO]],"mmm"))) -> ABR | Y374: Renato de Castro | Z374: Sergio Mench do Prado | AA374: Cláudio Mecenas
...
